Workbook
Name FolderPath: #REF!

Sheet Plan Indicativo 2024 - 2027
A1: Meta de resultado | AC1: Programación física del cuatrienio | AG1: PROYECTOS | AM1: EJECUCIÓN 2024 | AP1: EJECUCIÓN 2025 | AS1: EJECUCIÓN 2026 | AV1: EJECUCIÓN ACUMULADA | AY1: 2024 | BJ1: 2025 | BU1: 2026 | CF1: 2027 | CQ1: GRAN TOTAL | CR1: OBSERVACIONES
AH2: PROGRAMADO | AI2: EJECUTADO-EJECUCIÓN | AJ2: PROGRAMADO | AK2: EJECUTADO-EJECUCIÓN
A3: Codigo Meta | B3: Serie Numero | C3: Línea Estratégica | D3: Indicador de resultado | E3: Línea base | F3: Unidad de Medida | G3: Año base | H3: Fuente | I3: Meta cuatrienio | J3: ODS | K3: Sector PDD | L3: Numero Programa PDD | M3: Programa PDD | N3: Sector de inversión | O3: Código del sector | P3: Programa Presupuestal | Q3: Código del programa | R3: Producto | S3: Código del producto | T3: Indicador de producto principal | U3: código de indicador principal | V3: Descripción | W3: Medido a través de | X3: Tiene EDT | Y3: Unidad de medida2 | Z3: Meta de cuatrenio | AA3: Tipo de Acumulación | AB3: Responsable | AC3: Meta Física Esperada 2024 | AD3: Meta Física Esperada 2025 | AE3: Meta Física Esperada 2026 | AF3: Meta Física Esperada 2027 | AG3: PROYECTOS 2024 | AH3: PROYECTOS Y/O GESTIONES PROGRAMADOS 2025 | AI3: PROYECTOS 2025 | AJ3: PROYECTOS/GESTIONES PROGRAMADAS 2026 | AK3: PROYECTOS 2026 | AL3: PROYECTOS 2027 | AM3: EJECUCIÓN 2024 | AN3: PORCENTAJE DE EJECUCIÓN 2024 | AO3: CATEGORÍA DE EJECUCIÓN FÍSICA 2024 | AP3: EJECUCIÓN 2025 | AQ3: PORCENTAJE DE EJECUCIÓN 2025 | AR3: CATEGORÍA DE EJECUCIÓN FÍSICA 2025 | AS3: EJECUCIÓN 2026 | AT3: PORCENTAJE DE EJECUCIÓN 2026 | AU3: CATEGORÍA DE EJECUCIÓN FÍSICA 2026 | AV3: EJECUCIÓN ACUMULADA | AW3: PORCENTAJE DE EJECUCIÓN ACUMULADA | AX3: CATEGORÍA DE EJECUCIÓN ACUMULADA | AY3: Programación Recursos propios ICLD24 | AZ3: Programación Recursos propios ICDE24 | BA3: Programación SGP Educación24 | BB3: Programación SGP Salud24 | BC3: Programación SGP APSB24 | BD3: Programación Cofinanciación Municipio24 | BE3: Programación Cofinanciación Nación24 | BF3: Programación Crédito24 | BG3: Programación Regalías24 | BH3: Programación Otras Fuentes24 | BI3: Programación TOTAL24 | BJ3: Programación Recursos propios ICLD25 | BK3: Programación Recursos propios ICDE25 | BL3: Programación SGP Educación25 | BM3: Programación SGP Salud25 | BN3: Programación SGP APSB25 | BO3: Programación Cofinanciación Municipio25 | BP3: Programación Cofinanciación Nación25 | BQ3: Programación Crédito25 | BR3: Programación Regalías25 | BS3: Programación Otras Fuentes25 | BT3: Programación TOTAL25 | BU3: Programación Recursos propios ICLD26 | BV3: Programación Recursos propios ICDE26 | BW3: Programación SGP Educación26 | BX3: Programación SGP Salud26 | BY3: Programación SGP APSB26 | BZ3: Programación Cofinanciación Municipio26 | CA3: Programación Cofinanciación Nación26 | CB3: Programación Crédito26 | CC3: Programación Regalías26 | CD3: Programación Otras Fuentes26 | CE3: Programación TOTAL26 | CF3: Programación Recursos propios ICLD27 | CG3: Programación Recursos propios ICDE27 | CH3: Programación SGP Educación27 | CI3: Programación SGP Salud27 | CJ3: Programación SGP APSB27 | CK3: Programación Cofinanciación Municipio27 | CL3: Programación Cofinanciación Nación27 | CM3: Programación Crédito27 | CN3: Programación Regalías27 | CO3: Programación Otras Fuentes27 | CP3: Programación TOTAL27 | CQ3: GRAN TOTAL | CR3: OBSERVACIONES SEGUIMIENTO | CS3: OBSERVACIONES
A4: MT001 | B4: 2 | C4: Transformación del Ser Humano | D4: Porcentaje de ejecución de las actividades del plan de acción de la “Política pública diferencial para la primera infancia, la infancia y adolescencia y el fortalecimiento familiar, porque en Sucre, ser niño, niña o adolescente cuenta, 2019-2029” | E4: 0,5 | F4: Porcentaje | G4: 2023 | H4: Informe de avance Politica para la primera infancia, la infancia y adolescencia y el fortalecimiento familiar | I4: 0,75 | J4: 3. Salud y bienestar | K4: Inclusión Social | L4: 1 | M4: Primera infancia, infancia y adolescencia con garantía de derechos y Oportunidades | N4: Inclusión Social y Reconciliación | O4: 41 | P4: Desarrollo integral de la primera infancia a la juventud, y fortalecimiento de las capacidades de las familias de niñas, niños y adolescentes | Q4: 4102 | R4: Servicio de protección integral a niños, niñas, adolescentes y jóvenes | S4: 4102052 | T4: Niños, niñas, adolescentes y jóvenes beneficiados | U4: 410205200 | V4: Servicios enfocados a garantizar los derechos fundamentales , la prevención de amenazas o vulneración y restablecimiento de derechos. | W4: Número de niños, niñas, adolescentes y jóvenes | X4: No | Y4: Número | Z4: 1500 | AA4: Acumulativo | AB4: Secretaria de Inclusión Social, Mujer y Equidad de Genero | AC4: 200 | AD4: 450 | AE4: 450 | AF4: 400 | AG4: APOYO A LA MESA DE PARTICIPACIÓN DE NIÑOS, NIÑAS Y ADOLESCENTES 2024 EN EL DEPATRTAMENTO DE SUCRE (BPIN: Por Gestión) (Meta del Proyecto: 1050) (Ejecución 2024: 1050) | AH4: FOMENTO Y FORTALECIMIENTO DE UNIDADES PRODUCTIVAS A FAMILIAS CON NIÑOS, NIÑAS Y ADOLECENTES TRABAJADORES EN EL DEPARTAMENTYO DE SUCRE (Tipo Banco: Banco de Gestiones) (Meta de la gestión: ) APOYO A LA MESA DE PARTICIPACIÓN DE NIÑOS, NIÑAS Y ADOLESCENTES CAMPAMENTO 2025 EN EL DEPARTAMENTO DE SUCRE (Tipo Banco: Banco de Gestiones) (Meta de la gestión: 26) IMPLEMENTACIÓN DE LA ESTRETEGIA MI TERRITORIO SIN VIOLENCIA (Tipo Banco: Banco de Gestiones) (Meta de la gestión: 574) FORTALECIMIENTO DE LA INICIATIVA PRESENTADA EN LAS MESAS SUBREGIONALES DE PARTICIPACIÓN DE NIÑOS, NIÑAS Y ADOLESCENTES (BPIN: ) (Tipo de Banco: Sin Tipo de Banco) | AI4: APOYO A LA MESA DE PARTICIPACIÓN DE NIÑOS, NIÑAS Y ADOLESCENTES CAMPAMENTO 2025 EN EL DEPARTAMENTO DE SUCRE (Tipo de banco: Banco de Gestiones) (Meta de la gestión: 26) (Ejecutado: 26) IMPLEMENTACIÓN DE LA ESTRETEGIA MI TERRITORIO SIN VIOLENCIA (Tipo de banco: Banco de Gestiones) (Meta de la gestión: 574) (Ejecutado: 643) | AJ4: MESAS REGIONALES DE NIÑOS, NIÑAS Y ADOLESCENTES 2026 Implementación DE ACCIONES DE APOYO PSICOSOCIAL COMO ESTRATEGIA FRENTE A LAS PROBLEMÁTICAS DE SALUD MENTAL EN EL DEPARTAMENTO DE Sucre (BPIN: 202500000050658) (Meta del proyecto: 1040) (Tipo de Banco: Banco Territorial) Desarrollo de talleres para la prevención de la violencia - campaña mi territorio sin violencia. (Meta Programada: 450) (Tipo de Banco: Banco de Gestiones) | AK4: Desarrollo de talleres para la prevención de la violencia - campaña mi territorio sin violencia. (Meta programada: 450) (Ejecución: 246) (Tipo de banco: Banco de Gestiones) | AL4: FORTALECIMIENTO DE LA INICIATIVA PRESENTADA EN LAS MESAS SUBREGIONALES DE PARTICIPACIÓN DE NIÑOS, NIÑAS Y ADOLESCENTES (Bpin: ) | AM4: 1050 | AN4: 1 | AO4: Superior | AP4: 669 | AQ4: 1 | AR4: Superior | AS4: 246 | AT4: 1 | AU4: Superior | AV4: 1965 | AW4: 1 | AX4: Superior | AY4: 60000000 | AZ4: 0 | BA4: 0 | BB4: 0 | BC4: 0 | BD4: 0 | BE4: 0 | BF4: 0 | BG4: 0 | BH4: 0 | BI4: 60000000 | BJ4: 63000000 | BK4: 0 | BL4: 0 | BM4: 0 | BN4: 0 | BO4: 0 | BP4: 0 | BQ4: 0 | BR4: 0 | BS4: 0 | BT4: 63000000 | BU4: 66150000 | BV4: 0 | BW4: 0 | BX4: 0 | BY4: 0 | BZ4: 0 | CA4: 0 | CB4: 0 | CC4: 0 | CD4: 0 | CE4: 66150000 | CF4: 69457500 | CG4: 0 | CH4: 0 | CI4: 0 | CJ4: 0 | CK4: 0 | CL4: 0 | CM4: 0 | CN4: 0 | CO4: 0 | CP4: 69457500 | CQ4: 258607500 | CR4: 03/10/2024: se reviso la meta establecida con la profesional encargada de esta y se determino un error en el establecimiento de esta, solicita bajar de 1500 a 800 como esta la distribución por vigencia, teniendo en cuenta que esta meta ya se encuentra aprobada por asamblea, no puede hacerse una reducción, por lo que se solicita redistribución en vigencias, Actividad realizada por Gestión. | CS4: Campaña para el fomento del acceso de los niños, niñas y adolescentes a las ofertas institucionales y campaña mi territorio sin violencias.
A5: MT002 | B5: 3 | C5: Transformación del Ser Humano | D5: Porcentaje de ejecución de las actividades del plan de acción de la “Política pública diferencial para la primera infancia, la infancia y adolescencia y el fortalecimiento familiar, porque en Sucre, ser niño, niña o adolescente cuenta, 2019-2029” | E5: 0,5 | F5: Porcentaje | G5: 2023 | H5: Informe de avance Politica para la primera infancia, la infancia y adolescencia y el fortalecimiento familiar | I5: 0,75 | J5: 3. Salud y bienestar | K5: Inclusión Social | L5: 1 | M5: Primera infancia, infancia y adolescencia con garantía de derechos y Oportunidades | N5: Gobierno Territorial | O5: 45 | P5: Fortalecimiento del buen gobierno para el respeto y garantía de los derechos humanos | Q5: 4502 | R5: Servicio de educación informal | S5: 4502034 | T5: Personas Capacitadas | U5: 450203400 | V5: Corresponde al diseño y desarrollo de estrategias educativas que tienen como objetivo brindar oportunidades para apropiar, complementar, actualizar, perfeccionar, renovar o profundizar conocimientos, habilidades, técnicas y prácticas, este conocimiento libre y espontáneo adquirido, puede provenir de personas, entidades, medios masivos de comunicación, medios impresos, tradiciones, costumbres, comportamientos sociales y otros no estructurados y su duración es inferior a 160 horas. | W5: Número de personas | X5: No | Y5: Número | Z5: 200 | AA5: Acumulativo | AB5: Secretaria de Inclusión Social, Mujer y Equidad de Genero | AC5: 50 | AD5: 50 | AE5: 50 | AF5: 50 | AG5: CAPACITACION EN DERECHO INTERNACIONAL HUMANITARIO CON ENFASIS EN RECLUTAMIENTO (BPIN: Por Gestión) (Meta del Proyecto: 50) (Ejecución 2024: 50) MESAS DE PARTICIPACION DE NIÑAS, NIÑOS Y ADOLESCENTES (BPIN: Por Gestión) (Meta del Proyecto: 180) (Ejecución 2024: 180) CAPACITACIÓN A NIÑOS, NIÑAS Y ADOLESCENTES COMO DEFENSORES Y DEFENSORITOS (BPIN: Por Gestión) (Meta del Proyecto: 100) (Ejecución 2024: 100) | AJ5: IMPLEMENTACIÓN DE LA ESTRETEGIA MI TERRITORIO SIN VIOLENCIA (BPIN: Por Gestión) CAPACITACIÓN A NIÑOS, NIÑAS Y ADOLESCENTES (BPIN: Por Gestión) Jornada de sencibilización sobre cuidado ambiental en articulación con interaseo (Meta Programada: 50) (Tipo de Banco: Banco de Gestiones) | AK5: Jornada de sencibilización sobre cuidado ambiental en articulación con interaseo (Meta programada: 50) (Ejecución: 53) (Tipo de banco: Banco de Gestiones) | AL5: IMPLEMENTACIÓN DE LA ESTRETEGIA MI TERRITORIO SIN VIOLENCIA (Bpin: Por Gestión) CAPACITACIÓN A NIÑOS, NIÑAS Y ADOLESCENTES (Bpin: Por Gestión) | AM5: 330 | AN5: 1 | AO5: Superior | AP5: 0 | AQ5: 1 | AR5: Superior | AS5: 53 | AT5: 1 | AU5: Superior | AV5: 383 | AW5: 1 | AX5: Superior | AY5: 14000000 | AZ5: 0 | BA5: 0 | BB5: 0 | BC5: 0 | BD5: 0 | BE5: 0 | BF5: 0 | BG5: 0 | BH5: 0 | BI5: 14000000 | BJ5: 14700000 | BK5: 0 | BL5: 0 | BM5: 0 | BN5: 0 | BO5: 0 | BP5: 0 | BQ5: 0 | BR5: 0 | BS5: 0 | BT5: 14700000 | BU5: 15435000 | BV5: 0 | BW5: 0 | BX5: 0 | BY5: 0 | BZ5: 0 | CA5: 0 | CB5: 0 | CC5: 0 | CD5: 0 | CE5: 15435000 | CF5: 16206750 | CG5: 0 | CH5: 0 | CI5: 0 | CJ5: 0 | CK5: 0 | CL5: 0 | CM5: 0 | CN5: 0 | CO5: 0 | CP5: 16206750 | CQ5: 60341750 | CR5: El proyecto de mi territorio sin violencia, está programado para 2025, 2026 y 2027 en cumplimiento de la política pública. Sin embargo, se tiene una estrategia del plan de desarrollo que se gestionaría por valor de $3000 millones, si esta se gestiona, no hay necesidad de hacer cada año los proyectos pequeños 03/10/2024: Se encuentra una discrepancia engtre la meta de cuatrenio que se encuentra en 200 y las metas por vigencias que estan por 100, dando una cantidad de 400, por lo cual se procede de confornidad a lo definido por el profesional a ajustar la meta de cuatrenio a 400. | CS5: Funcionarios capacitados y mujeres capacitadas con formaciònes para el trabajo y su autonomia productiva, Campañas de prevenciòn de la fobia, bifobia y transfobia. Niños, niñas y adolescentes formados y capacitados
A6: MT003 | B6: 3 | C6: Transformación del Ser Humano | D6: Porcentaje de ejecución de las actividades del Plan de Acción de la Política Pública Departamental de Juventudes "Sucre Territorio Joven" | E6: 0,26700000000000002 | F6: Porcentaje | G6: 2023 | H6: Informe Polìtica Pùblica Departamental de Juventudes | I6: 0,5 | J6: 3. Salud y bienestar | K6: Inclusión Social | L6: 2 | M6: Sucre territorio Joven | N6: Trabajo | O6: 36 | P6: Generación y formalización del empleo | Q6: 3602 | R6: Servicio de gestión para el emprendimiento solidario | S6: 3602003 | T6: Emprendimientos solidarios dinamizados | U6: 360200300 | V6: Se trata de la gestión que realiza Organizaciones Solidarias para la conformación de emprendimientos. Esto podrá incluir conformación, fortalecimiento, asesoría, empresas, modelo de evaluación, personas sensibilizadas, entre otros, que oriente la creación y fortalecimiento de dichas organizaciones. | W6: Número de emprendimientos solidarios | X6: No | Y6: Número | Z6: 500 | AA6: Acumulativo | AB6: Secretaria de Inclusión Social, Mujer y Equidad de Genero | AC6: 40 | AD6: 0 | AE6: 310 | AF6: 150 | AG6: APOYO LOGISTICO PARA LA IMPLEMENTACIÓN DEL LABORATORIO DE EMPREDIMIENTO PARA JOVENES VULNERABLES DEL DEPARTAMENTO DE SUCRE (BPIN: Por Gestión) (Meta del Proyecto: 300) (Ejecución 2024: 32) | AH6: APOYO LOGISTICO PARA LA IMPLEMENTACIÓN DEL LABORATORIO DE EMPREDIMIENTO PARA JOVENES VULNERABLES DEL DEPARTAMENTO DE SUCRE (Tipo Banco: Banco de Gestiones) (Meta de la gestión: ) IMPLEMENTACIÓN DE ACCIONES DE APOYO INTEGRAL PARA EL FORTALECIMIENTO ECONÓMICO Y EL CUMPLIMIENTO DE LA POLÍTICA PÚBLICA DEPARTAMENTAL DE JÓVENES EN EL DEPARTAMENTO DE SUCRE (Tipo Banco: Banco de Gestiones) (Meta de la gestión: 1500) | AM6: 32 | AN6: 0.8 | AO6: Alto | AT6: 0 | AU6: Minimo | AV6: 32 | AW6: 0.064 | AX6: Minimo | AY6: 50000000 | AZ6: 0 | BA6: 0 | BB6: 0 | BC6: 0 | BD6: 0 | BE6: 0 | BF6: 0 | BG6: 0 | BH6: 0 | BI6: 50000000 | BJ6: 52500000 | BK6: 0 | BL6: 0 | BM6: 0 | BN6: 0 | BO6: 0 | BP6: 0 | BQ6: 0 | BR6: 0 | BS6: 0 | BT6: 52500000 | BU6: 55125000 | BV6: 0 | BW6: 0 | BX6: 0 | BY6: 0 | BZ6: 0 | CA6: 0 | CB6: 0 | CC6: 0 | CD6: 0 | CE6: 55125000 | CF6: 57881250 | CG6: 0 | CH6: 0 | CI6: 0 | CJ6: 0 | CK6: 0 | CL6: 0 | CM6: 0 | CN6: 0 | CO6: 0 | CP6: 57881250 | CQ6: 215506250 | CR6: Indican que para 1000 jóvenes pero la meta es 500 03/10/2024: Se indica que para el mes de noviembre se realizara un laboratorio de emprendimiento e innovación con el cual se alcanzara la meta de 500 emprendimientos, esto por Gestión. Se tienen programada la realización del evento para el 28 y 29 de Novimebtre. | CS6: Jovenes capacitidos para el fomento del empredimiento
A7: MT004 | B7: 4 | C7: Transformación del Ser Humano | D7: Porcentaje de ejecución de las actividades del Plan de Acción de la Política Pública Departamental de Juventudes "Sucre Territorio Joven" | E7: 0,26700000000000002 | F7: Porcentaje | G7: 2023 | H7: Informe Polìtica Pùblica Departamental de Juventudes | I7: 0,5 | J7: 3. Salud y bienestar | K7: Inclusión Social | L7: 2 | M7: Sucre territorio Joven | N7: Inclusión Social y Reconciliación | O7: 41 | P7: Desarrollo integral de la primera infancia a la juventud, y fortalecimiento de las capacidades de las familias de niñas, niños y adolescentes | Q7: 4102 | R7: Servicio de asistencia técnica en el ciclo de políticas públicas de familia y otras relacionadas | S7: 4102041 | T7: Instituciones y entidades asistidas técnicamente | U7: 410204100 | V7: Comprende la capacitación, asesoría y acompañamiento en el diseño e implementación de programas dirigidos a las familias y a la garantía de sus derechos y los de sus integrantes . | W7: Número de instituciones y organizaciones | X7: No | Y7: Número | Z7: 26 | AA7: No acumulativo | AB7: Secretaria de Inclusión Social, Mujer y Equidad de Genero | AC7: 26 | AD7: 26 | AE7: 26 | AF7: 26 | AG7: FORTALECIMIENTO A LOS SISTEMAS DE PARTICIPACIÓN JUVENIL MUNICIPALES (BPIN: Por Gestión) (Meta del Proyecto: 24) (Ejecución 2024: 24) | AH7: ASISTENCIAS TECNICAS A LOS SUBSISTEMAS DE PARTICIPACIÓN JUVENIL MUNICIPALES. (Tipo Banco: Banco de Gestiones) (Meta de la gestión: 26) | AI7: ASISTENCIAS TECNICAS A LOS SUBSISTEMAS DE PARTICIPACIÓN JUVENIL MUNICIPALES. (Tipo de banco: Banco de Gestiones) (Meta de la gestión: 26) (Ejecutado: 26) | AJ7: FORTALECIMIENTO A LOS SISTEMAS DE PARTICIPACIÓN JUVENIL MUNICIPALES (Por Gestión) (BPIN: Por Gestión) (Tipo de Banco: Sin Tipo de Banco) | AL7: FORTALECIMIENTO A LOS SISTEMAS DE PARTICIPACIÓN JUVENIL MUNICIPALES (Bpin: Por Gestión) | AM7: 24 | AN7: 0.92307692 | AO7: Alto | AP7: 26 | AQ7: 1 | AR7: Superior | AT7: 0 | AU7: Minimo | AV7: 50 | AW7: 1 | AX7: Superior | AY7: 30000000 | AZ7: 0 | BA7: 0 | BB7: 0 | BC7: 0 | BD7: 0 | BE7: 0 | BF7: 0 | BG7: 0 | BH7: 0 | BI7: 30000000 | BJ7: 31500000 | BK7: 0 | BL7: 0 | BM7: 0 | BN7: 0 | BO7: 0 | BP7: 0 | BQ7: 0 | BR7: 0 | BS7: 0 | BT7: 31500000 | BU7: 33075000 | BV7: 0 | BW7: 0 | BX7: 0 | BY7: 0 | BZ7: 0 | CA7: 0 | CB7: 0 | CC7: 0 | CD7: 0 | CE7: 33075000 | CF7: 34728750 | CG7: 0 | CH7: 0 | CI7: 0 | CJ7: 0 | CK7: 0 | CL7: 0 | CM7: 0 | CN7: 0 | CO7: 0 | CP7: 34728750 | CQ7: 129303750 | CR7: 03/10/2024: Se ha brindado asistencia técnica a los sistemas de participación juvenil municipales, Por Gestión, se tenia previsto la formulación de un proyecto pero este no cuenta con financiación. Se brindo asistencia a las dependencias encargadas de juventud de cada municipio -enlaces de juventud o secretarios de gobierno y miembros de consejos y plataformas municipales de juventud, faltando solo los municipios de Sampues y Majagual. | CS7: Fortalecer y hacer seguimiento a la Ruta Integral de Atenciones -RIA del Departamento.y observatorios de familia operando en el departamento de Sucre
A8: MT005 | B8: 2 | C8: Transformación del Ser Humano | D8: Porcentaje de ejecución de las actividades del Plan de acción de la Política Pública para el fortalecimiento integral de las familias de sucre 2023-2037 | E8: 0 | F8: Porcentaje | G8: 2023 | H8: Informe de avance Política Pública para el fortalecimiento integral de las familias | I8: 0,25 | J8: 3. Salud y bienestar 10- Reducción de las desigualdades. | K8: Inclusión Social | L8: 3 | M8: Familias con Oportunidades | N8: Inclusión Social y Reconciliación | O8: 41 | P8: Desarrollo integral de la primera infancia a la juventud, y fortalecimiento de las capacidades de las familias de niñas, niños y adolescentes | Q8: 4102 | R8: Servicio de asistencia técnica en el ciclo de políticas públicas de familia y otras relacionadas | S8: 4102041 | T8: Instituciones y entidades asistidas técnicamente | U8: 410204100 | V8: Comprende la capacitación, asesoría y acompañamiento en el diseño e implementación de programas dirigidos a las familias y a la garantía de sus derechos y los de sus integrantes . | W8: Número de instituciones y organizaciones | X8: No | Y8: Número | Z8: 26 | AA8: No acumulativo | AB8: Secretaria de Inclusión Social, Mujer y Equidad de Genero | AC8: 26 | AD8: 26 | AE8: 26 | AF8: 26 | AG8: ASISTENCIA TÉCNICA A LOS 26 OBSERVATORIOS MUNICIPALES DE SUCRE (BPIN: Por Gestión) (Meta del Proyecto: 26) (Ejecución 2024: 26) | AH8: Realizar asistencias tecnicas a los 26 observatorios creados en los 26 mucipios del departamento de sucre, en el fortalecimiento institucional. (Tipo Banco: Banco de Gestiones) (Meta de la gestión: 26) FORTALECIMIENTO INSTITUCIONAL DE LOS OBSERVATORIOS DE FAMILIA EN EL DEPARTAMENTO DE SUCRE (BPIN: ) (Tipo de Banco: Banco Territorial) | AI8: Realizar asistencias tecnicas a los 26 observatorios creados en los 26 mucipios del departamento de sucre, en el fortalecimiento institucional. (Tipo de banco: Banco de Gestiones) (Meta de la gestión: 26) (Ejecutado: 26) | AJ8: ASISTENCIA TÉCNICA A LOS 26 OBSERVATORIOS MUNICIPALES DE SUCRE (Tipo de Banco: Sin Tipo de Banco) Implementación DE ACCIONES DE APOYO PSICOSOCIAL COMO ESTRATEGIA FRENTE A LAS PROBLEMÁTICAS DE SALUD MENTAL EN EL DEPARTAMENTO DE Sucre (BPIN: 202500000050658) (Meta del proyecto: 26) (Tipo de Banco: Banco Territorial) Asistencia técnica virtual a los observatorios municipales de familia del Departamento de Sucre, en lo relacionado en la implementación de la politica pública de familia y al plan de desarrollo. (Meta Programada: 26) (Tipo de Banco: Banco de Gestiones) | AK8: Asistencia técnica virtual a los observatorios municipales de familia del Departamento de Sucre, en lo relacionado en la implementación de la politica pública de familia y al plan de desarrollo. (Meta programada: 26) (Ejecución: 19) (Tipo de banco: Banco de Gestiones) | AL8: ASISTENCIA TÉCNICA A LOS 26 OBSERVATORIOS MUNICIPALES DE SUCRE (Bpin: ) (Tipo de banco: Sin Tipo de Banco) | AM8: 26 | AN8: 1 | AO8: Superior | AP8: 26 | AQ8: 1 | AR8: Superior | AS8: 19 | AT8: 0.73076923 | AU8: Alto | AV8: 71 | AW8: 1 | AX8: Superior | AY8: 30000000 | AZ8: 0 | BA8: 0 | BB8: 0 | BC8: 0 | BD8: 0 | BE8: 0 | BF8: 0 | BG8: 0 | BH8: 0 | BI8: 30000000 | BJ8: 31500000 | BK8: 0 | BL8: 0 | BM8: 0 | BN8: 0 | BO8: 0 | BP8: 0 | BQ8: 0 | BR8: 0 | BS8: 0 | BT8: 31500000 | BU8: 33075000 | BV8: 0 | BW8: 0 | BX8: 0 | BY8: 0 | BZ8: 0 | CA8: 0 | CB8: 0 | CC8: 0 | CD8: 0 | CE8: 33075000 | CF8: 34728750 | CG8: 0 | CH8: 0 | CI8: 0 | CJ8: 0 | CK8: 0 | CL8: 0 | CM8: 0 | CN8: 0 | CO8: 0 | CP8: 34728750 | CQ8: 129303750 | CR8: El año 2024 se va a hacer por gestión | CS8: Fortalecer y hacer seguimiento a la Ruta Integral de Atenciones -RIA del Departamento.y observatorios de familia operando en el departamento de Sucre
A9: MT006 | B9: 1 | C9: Transformación del Ser Humano | D9: Porcentaje de ejecución de las actividades del plan de acción de la “Política pública diferencial para la primera infancia, la infancia y adolescencia y el fortalecimiento familiar, porque en Sucre, ser niño, niña o adolescente cuenta, 2019-2029” | E9: 0,5 | F9: Porcentaje | G9: 2023 | H9: Informe de avance Politica para la primera infancia, la infancia y adolescencia y el fortalecimiento familiar | I9: 0,75 | J9: 3. Salud y bienestar | K9: Inclusión Social | L9: 1 | M9: Primera infancia, infancia y adolescencia con garantía de derechos y Oportunidades | N9: Inclusión Social y Reconciliación | O9: 41 | P9: Desarrollo integral de la primera infancia a la juventud, y fortalecimiento de las capacidades de las familias de niñas, niños y adolescentes | Q9: 4102 | R9: Servicio de atención integral a la primera infancia | S9: 4102001 | T9: Niños y niñas atendidos en Servicio integrales | U9: 410200100 | V9: Servicio dispuestos para atender a los niños y niñas en primera infancia, con el fin de promover su desarrollo integral a través de la atención en educación inicial, cuidado calificado, salud, nutrición, protección y acompañamiento familiar. | W9: Número de niños y niñas | X9: No | Y9: Número | Z9: 1230 | AA9: No acumulativo | AB9: Secretaria de Inclusión Social, Mujer y Equidad de Genero | AC9: 1230 | AD9: 1230 | AE9: 1230 | AF9: 1230 | AG9: APOYO PARA LA REALIZACIÓN DE ACTIVIDADES CULTURALES Y RECREATIVAS EN EL MARCO DEL MES DE LA NIÑEZ EN EL DEPARTAMENTO DE SUCRE (BPIN: 2024002700041) (Meta del Proyecto: 1769) (Ejecución 2024: 1769) | AH9: APOYO NUTRICIONAL A NIÑAS Y NIÑOS DE LA PRIMERA INFANCIA CON DESNUTRICIÓN Y EN RIESGO DE DESNUTRICIÓN EN EL DEPARTAMENTO DE SUCRE (BPIN: ) (Tipo de Banco: Banco Territorial) APOYO PARA LA REALIZACIÓN DE ACTIVIDADES RECREATIVAS Y LÚDICAS EN EL MARCO DEL MES DE LA NIÑEZ VIGENCIA 2025, EN EL DEPARTAMENTO DE SUCRE (BPIN: 202400000004298) (Tipo de Banco: Banco Territorial) APOYO NUTRICIONAL A FAMILIAS CON NIÑAS Y NIÑOS MENORES DE 5 AÑOS CON DESNUTRICIÓN Y RIESGO DE DESNUTRICIÓN EN EL DEPARTAMENTO DE SUCRE (BPIN: ) (Tipo de Banco: Banco Territorial) APOYO PARA LA ELABORACIÓN E IMPLEMENTACIÓN DEL MAPA DE LA RUTA INTEGRAL DE ATENCIÓN A LA PRIMERA INFANCIA Y ADOLESCENCIA - RIA EN LOS MUNICIPIOS DEL DEPARTAMENTO DE SUCRE (BPIN: 2024002700095) (Tipo de Banco: Banco Territorial) | AI9: Apoyo PARA LA ELABORACIÓN E IMPLEMENTACIÓN DEL MAPA DE LA RUTA INTEGRAL DE ATENCIÓN A LA PRIMERA INFANCIA Y ADOLESCENCIA - RIA EN LOS MUNICIPIOS DEL DEPARTAMENTO DE Sucre (Bpin: 2024002700095) (Tipo de Banco: Banco Territorial) (Meta total del indicador: 70081.0) (Meta total de la vigencia: 70081.0) (Ejecutado: 70081.0) Apoyo para la realización de actividades recreativas y lúdicas en el marco del mes de la niñez Vigencia 2025, en el Departamento de Sucre (Bpin: 202400000004298) (Tipo de Banco: Banco Territorial) (Meta total del indicador: 1320.0) (Meta total de la vigencia: 1320.0) (Ejecutado: 1320.0) | AJ9: Apoyo PARA LA REALIZACIÓN DE ACTIVIDADES RECREATIVAS, DE EMPRENDIMIENTO, JUEGO, CIENCIA Y TECNOLOGIA A NIÑOS Y NIÑAS DEL DEPARTAMENTO DE Sucre (BPIN: 202500000050596) (Meta del proyecto: 1358) (Tipo de Banco: Banco Territorial) (Estado en Portafolio: En Ejecución) APOYO PARA LA REALIZACIÓN DE ACTIVIDADES CULTURALES Y RECREATIVAS EN EL MARCO DEL MES DE LA NIÑEZ EN EL DEPARTAMENTO DE SUCRE (Tipo de Banco: Sin Tipo de Banco) FORTALECIMIENTO NUTRICIONAL A NIÑOS MENORES DE 5 AÑOS EN RIESGO DE DESNUTRICIÓN EN EL DEPARTAMENTO DE SUCRE (Tipo de Banco: Sin Tipo de Banco) | AL9: APOYO PARA LA REALIZACIÓN DE ACTIVIDADES CULTURALES Y RECREATIVAS EN EL MARCO DEL MES DE LA NIÑEZ EN EL DEPARTAMENTO DE SUCRE (Pendiente por formular) (Bpin: ) (Tipo de banco: Sin Tipo de Banco) FORTALECIMIENTO NUTRICIONAL A NIÑOS MENORES DE 5 AÑOS EN RIESGO DE DESNUTRICIÓN EN EL DEPARTAMENTO DE SUCRE (Bpin: ) (Tipo de banco: Sin Tipo de Banco) | AM9: 1769 | AN9: 1 | AO9: Superior | AP9: 71401 | AQ9: 1 | AR9: Superior | AT9: 1 | AU9: Superior | AV9: 73170 | AW9: 1 | AX9: Superior | AY9: 150000000 | AZ9: 0 | BA9: 0 | BB9: 0 | BC9: 0 | BD9: 0 | BE9: 0 | BF9: 0 | BG9: 0 | BH9: 0 | BI9: 150000000 | BJ9: 157500000 | BK9: 0 | BL9: 0 | BM9: 0 | BN9: 0 | BO9: 0 | BP9: 0 | BQ9: 0 | BR9: 0 | BS9: 0 | BT9: 157500000 | BU9: 165375000 | BV9: 0 | BW9: 0 | BX9: 0 | BY9: 0 | BZ9: 0 | CA9: 0 | CB9: 0 | CC9: 0 | CD9: 0 | CE9: 165375000 | CF9: 173643750 | CG9: 0 | CH9: 0 | CI9: 0 | CJ9: 0 | CK9: 0 | CL9: 0 | CM9: 0 | CN9: 0 | CO9: 0 | CP9: 173643750 | CQ9: 646518750 | CR9: Se dio orientación de mantenimiento porque se está programando sobrecumplir la meta con los proyectos que asociaron Se alcanzo el cumplimiento de la meta con la ejecución APOYO PARA LA REALIZACIÓN DE ACTIVIDADES CULTURALES Y RECREATIVAS EN EL MARCO DEL MES DE LA NIÑEZ EN EL DEPARTAMENTO DE SUCRE (2024002700041), en el cual se beneficiaror 1,769 niños y niñas 03/10/2024: se tenia una meta de 1230 por mantenimiento, en conversacion la profesional tresponsable de la meta detecta un error y solicita subir la meta a 1500 para el mes de la niñez. Se elimina la iniciativa IMPLEMEMENTACIÓN DEL PROGRAMA DE PUERICULTURA (Pendiente por formular), y se incluye en la iniciativa IMPLEMENTACIÓN DE LA ESTRETEGIA MI TERRITORIO SIN VIOLENCIA (Pendiente por formular) | CS9: Estrategia "mi territorio sin violencias", redes de instituciones y servicios destinados a la atención de la primera infancia y conmemoraciòn del mes del niño.
A10: MT007 | B10: 1 | C10: Transformación del Ser Humano | D10: Porcentaje de ejecución de las actividades del Plan de Acción de la Política Pública Departamental de Juventudes "Sucre Territorio Joven" | E10: 0,26700000000000002 | F10: Porcentaje | G10: 2023 | H10: Informe Polìtica Pùblica Departamental de Juventudes | I10: 0,5 | J10: 3. Salud y bienestar | K10: Inclusión Social | L10: 2 | M10: Sucre territorio Joven | N10: Gobierno Territorial | O10: 45 | P10: Fortalecimiento del buen gobierno para el respeto y garantía de los derechos humanos | Q10: 4502 | R10: Servicio de promoción a la participación ciudadana | S10: 4502001 | T10: Espacios de participación promovidos | U10: 450200100 | V10: Corresponde al diseño e implementación de acciones y estrategias que promuevan el ejercicio de la participación ciudadana para el respeto y garantía de los derechos humanos | W10: Número de iniciativas | X10: No | Y10: Número | Z10: 108 | AA10: Acumulativo | AB10: Secretaria de Inclusión Social, Mujer y Equidad de Genero | AC10: 16 | AD10: 31 | AE10: 31 | AF10: 30 | AG10: APOYO LOGÍSTICO PARA LA CONMEMORACIÓN DEL MES DE LA JUVENTUD EN EL DEPARTAMENTO DE SUCRE (BPIN: 2024002700096) (Meta del Proyecto: 9) (Ejecución 2024: 9) APOYO A LA PRIMERA CUMBRE REGIONAL DE JOVENES CARIBE 2024 EN EL DEPARTAMENTO DE SUCRE (BPIN: Por Gestión) (Meta del Proyecto: 1) (Ejecución 2024: 1) | AH10: Jornadas de promoción en las instituciones educativas para promover la participación de los jovenes en las elecciones de Consejos de Juventud Municipales. (Tipo Banco: Banco de Gestiones) (Meta de la gestión: 31) Apoyo logístico para la conmemoración del mes de la juventud 2025 en el Departamento de Sucre (BPIN: 202500000028886) (Tipo de Banco: Banco Territorial) APOYO A LA ENTREGA DE ESTÍMULOS DE CARÁCTER EDUCATIVO, CULTURAL Y RECREATIVO PARA LOS CONSEJEROS Y PLATAFORMADOS DEPARTAMENTALES DE JUVENTUD Y SUMINISTRO DE ELEMENTOS DE APOYO AL SISTEMA DE PARTICIPACIÓN JUVENIL DEL DEPARTAMENTO DE SUCRE (BPIN: ) (Tipo de Banco: Banco Territorial) APOYO AL FORTALECIMIENTO DEL SISTEMA DE PARTICIPACIÓN JUVENIL DURANTE LAS VIGENCIAS 2025 - 2026 EN EL DEPARTAMENTO DE SUCRE (BPIN: 202500000028900) (Tipo de Banco: Banco Territorial) APOYO LOGISTICO PARA EL FORTALECIMIENTO DEL SISTEMA DE PARTICIPACIÓN JUVENIL EN EL DEPARTAMENTO DE SUCRE (BPIN: 202400000001355) (Tipo de Banco: Banco Territorial) APOYO PARA EL FORTALECIMIENTO DEL SISTEMA DE PARTICIPACION JUVENIL DURANTE LAS VIGENCIAS 2025 - 2026 EN EL DEPARTAMENTO DE SUCRE (BPIN: ) (Tipo de Banco: Banco Territorial) APOYO LOGISTICO PARA LA CONMEMORACIÓN DEL MES DE LA JUVENTUD 2025 EN EL DEPARTAMENTO DE SUCRE (BPIN: ) (Tipo de Banco: Banco Territorial) | AI10: Apoyo logístico para la conmemoración del mes de la juventud 2025 en el Departamento de Sucre (Bpin: 202500000028886) (Tipo de Banco: Banco Territorial) (Meta total del indicador: 5.0) (Meta total de la vigencia: 5.0) (Ejecutado: 5.0) Jornadas de promoción en las instituciones educativas para promover la participación de los jovenes en las elecciones de Consejos de Juventud Municipales. (Tipo de banco: Banco de Gestiones) (Meta de la gestión: 31) (Ejecutado: 25) APOYO LOGISTICO PARA EL FORTALECIMIENTO DEL SISTEMA DE PARTICIPACIÓN JUVENIL EN EL DEPARTAMENTO DE SUCRE (BPIN: 202400000001355) (Tipo de banco: Banco Territorial) (Meta total del proyecto: 7) (Ejecutado: 7.0) | AJ10: Apoyo para el fomento de las oportunidades de los jovenes mediante la realización de Ferias Universitarias, espacios de emprendimiento y otros escenarios de participación en el departamento de Sucre (BPIN: 202600000005647) (Meta del proyecto: 2) (Tipo de Banco: Banco Territorial) (Estado en Portafolio: En gestión de recursos) Apoyo para el fortalecimiento del sistema de participación juvenil para la vigencia 2026 en el Departamento de Sucre (BPIN: 202600000003201) (Meta del proyecto: 14) (Tipo de Banco: Banco Territorial) (Estado en Portafolio: En gestión de recursos) APOYO AL FORTALECIMIENTO DEL SISTEMA DE PARTICIPACIÓN JUVENIL EN EL DEPARTAMENTO DE SUCRE (Pendiente de subsanaciones) (Tipo de Banco: Sin Tipo de Banco) APOYO LOGÍSTICO PARA LA CONMEMORACIÓN DEL MES DE LA JUVENTUD EN EL DEPARTAMENTO DE SUCRE APOYO A LA ENTREGA DE ESTÍMULOS DE CARÁCTER EDUCATIVO, CULTURAL Y RECREATIVO PARA LOS CONSEJEROS Y PLATAFORMADOS DEPARTAMENTALES DE JUVENTUD Y SUMINISTRO DE ELEMENTOS DE APOYO AL SISTEMA DE PARTICIPACIÓN JUVENIL DEL DEPARTAMENTO DE SUCRE APOYO A LA PRIMERA CUMBRE REGIONAL DE JOVENES CARIBE 2024 EN EL DEPARTAMENTO DE SUCRE Poseción del Consejo Departamental de Juventudes 2026-2027. Elección del Consejo Departamental de Juventudes 2026-2027. Espacio de socialización con la junta directiva y Comite de Concertación y Desición del Consejo Departamentalde Juventudes. (Meta Programada: 3) (Tipo de Banco: Banco de Gestiones) | AK10: Poseción del Consejo Departamental de Juventudes 2026-2027. Elección del Consejo Departamental de Juventudes 2026-2027. Espacio de socialización con la junta directiva y Comite de Concertación y Desición del Consejo Departamentalde Juventudes. (Meta programada: 3) (Ejecución: 3) (Tipo de banco: Banco de Gestiones) | AL10: APOYO A LA PRIMERA CUMBRE REGIONAL DE JOVENES CARIBE 2024 EN EL DEPARTAMENTO DE SUCRE. (Bpin: ) (Tipo de banco: Sin Tipo de Banco) APOYO LOGÍSTICO PARA LA CONMEMORACIÓN DEL MES DE LA JUVENTUD EN EL DEPARTAMENTO DE SUCRE (Bpin: ) APOYO A LA ENTREGA DE ESTÍMULOS DE CARÁCTER EDUCATIVO, CULTURAL Y RECREATIVO PARA LOS CONSEJEROS Y PLATAFORMADOS DEPARTAMENTALES DE JUVENTUD Y SUMINISTRO DE ELEMENTOS DE APOYO AL SISTEMA DE PARTICIPACIÓN JUVENIL DEL DEPARTAMENTO DE SUCRE (Bpin: ) APOYO AL FORTALECIMIENTO DEL SISTEMA DE PARTICIPACIÓN JUVENIL EN EL DEPARTAMENTO DE SUCRE (Bpin: ) | AM10: 10 | AN10: 0.625 | AO10: Alto | AP10: 37 | AQ10: 1 | AR10: Superior | AS10: 3 | AT10: 0.096774194 | AU10: Minimo | AV10: 50 | AW10: 0.46296296 | AX10: Medio | AY10: 166000000 | AZ10: 0 | BA10: 0 | BB10: 0 | BC10: 0 | BD10: 0 | BE10: 0 | BF10: 0 | BG10: 0 | BH10: 0 | BI10: 166000000 | BJ10: 174300000 | BK10: 0 | BL10: 0 | BM10: 0 | BN10: 0 | BO10: 0 | BP10: 0 | BQ10: 0 | BR10: 0 | BS10: 0 | BT10: 174300000 | BU10: 183015000 | BV10: 0 | BW10: 0 | BX10: 0 | BY10: 0 | BZ10: 0 | CA10: 0 | CB10: 0 | CC10: 0 | CD10: 0 | CE10: 183015000 | CF10: 192165750 | CG10: 0 | CH10: 0 | CI10: 0 | CJ10: 0 | CK10: 0 | CL10: 0 | CM10: 0 | CN10: 0 | CO10: 0 | CP10: 192165750 | CQ10: 715480750 | CR10: se adelantará proceso contractual este año y se solicitará vigencias futuras para ejecución 03/10/2024: Se tenia una meta de 108 espacios en el cuatrienio, se establece por incremento, por solicitud del profesional a cargo se redistribuyen las metas por vigencia. | CS10: Sesiones Consejo Departamental de Juventudes y asiistencias tecnicas a las alcaldias municipales para el fortalecimiento del Subsistema de participaciòn juvenil
A11: MT008 | B11: 2 | C11: Transformación del Ser Humano | D11: Porcentaje de ejecución de las actividades del Plan de Acción de la Política Pública Departamental de Juventudes "Sucre Territorio Joven" | E11: 0,26700000000000002 | F11: Porcentaje | G11: 2023 | H11: Informe Polìtica Pùblica Departamental de Juventudes | I11: 0,5 | J11: 3. Salud y bienestar | K11: Inclusión Social | L11: 2 | M11: Sucre territorio Joven | N11: Trabajo | O11: 36 | P11: Fomento de la investigación, desarrollo tecnológico e innovación del sector trabajo | Q11: 3605 | R11: Servicios de información implementados | S11: 3605011 | T11: Sistema de información implementados | U11: 360501100 | V11: Corresponde al proceso que mejora en la disposición de la información para asegurar que sea accesible, confiable y oportuna. | W11: Número de sistemasde información | X11: Sí | Y11: Número | Z11: 1 | AA11: Acumulativo | AB11: Secretaria de Inclusión Social, Mujer y Equidad de Genero | AC11: 0 | AD11: 0 | AE11: 1 | AF11: 0 | AH11: CONVENIO CON LA CAJA DE COMPENSACIÓN DE COMFASUCRE PARA IMPLEMENTACIÓN DE LA ORDENANZA 028 DE 2022. (Tipo Banco: Banco de Gestiones) (Meta de la gestión: 1) IMPLEMENTACIÓN DE ACTIVIDADES DE CORTE TECNOLOGICO EN CUMPLIMIENTO DE LA ORDENANZA 028 DE 2022 PARA LA PLATAFORMA DE JUVENTUDES DEL DEPARTAMENTO DE SUCRE (BPIN: 2024002700093) (Tipo de Banco: Banco Territorial) | AJ11: CONVENIO CON LA CAJA DE COMPENSACIÓN DE COMFASUCRE PARA IMPLEMENTACIÓN DE LA ORDENANZA 028 DE 2022. (Meta Programada: 1) (Tipo de Banco: Banco de Gestiones) | AK11: CONVENIO CON LA CAJA DE COMPENSACIÓN DE COMFASUCRE PARA IMPLEMENTACIÓN DE LA ORDENANZA 028 DE 2022. (Meta programada: 1) (Ejecución: 1) (Tipo de banco: Banco de Gestiones) | AS11: 1 | AT11: 1 | AU11: Superior | AV11: 1 | AW11: 1 | AX11: Superior | AY11: 50000000 | AZ11: 0 | BA11: 0 | BB11: 0 | BC11: 0 | BD11: 0 | BE11: 0 | BF11: 0 | BG11: 0 | BH11: 0 | BI11: 50000000 | BJ11: 52500000 | BK11: 0 | BL11: 0 | BM11: 0 | BN11: 0 | BO11: 0 | BP11: 0 | BQ11: 0 | BR11: 0 | BS11: 0 | BT11: 52500000 | BU11: 55125000 | BV11: 0 | BW11: 0 | BX11: 0 | BY11: 0 | BZ11: 0 | CA11: 0 | CB11: 0 | CC11: 0 | CD11: 0 | CE11: 55125000 | CF11: 57881250 | CG11: 0 | CH11: 0 | CI11: 0 | CJ11: 0 | CK11: 0 | CL11: 0 | CM11: 0 | CN11: 0 | CO11: 0 | CP11: 57881250 | CQ11: 215506250 | CR11: Se tiene previsto la contratación y ejecutación durante la vigencia 2025, no cuenta con financiación, pero se esta realizando gestiones para la aplicación de un software de otras entidades. | CS11: Pllataforma ordenanza empleo joven
A12: MT009 | B12: 5 | C12: Transformación del Ser Humano | D12: Porcentaje de ejecución de las actividades del Plan de Acción de la Política Pública Departamental de Juventudes "Sucre Territorio Joven" | E12: 0,26700000000000002 | F12: Porcentaje | G12: 2023 | H12: Informe Polìtica Pùblica Departamental de Juventudes | I12: 0,5 | J12: 3. Salud y bienestar | K12: Inclusión Social | L12: 2 | M12: Sucre territorio Joven | N12: Inclusión Social y Reconciliación | O12: 41 | P12: Desarrollo integral de la primera infancia a la juventud, y fortalecimiento de las capacidades de las familias de niñas, niños y adolescentes | Q12: 4102 | R12: Servicios de educación informal a niños, niñas, adolescentes y jóvenes para el reconocimiento de sus derechos | S12: 4102045 | T12: Personas capacitadas | U12: 410204500 | V12: Servicios mediante los cuales se socializan a los niños, niñas, adolescentes y jóvenes; al igual que a sus padres, madres, cuidadores y docentes, los temas relacionados con el reconocimiento de los derechos de la niñez, la adolescencia y la juventud. | W12: Número de personas | X12: No | Y12: Número | Z12: 150 | AA12: Acumulativo | AB12: Secretaria de Inclusión Social, Mujer y Equidad de Genero | AC12: 0 | AD12: 50 | AE12: 50 | AF12: 50 | AH12: CAMPAÑA SUCRE TERRITORIO JOVEN EN LA INSTITUCIÓN EDUCATIVA ALTOS DEL ROSARIO Y CAPACITACIÓN A LOS CONSEJEROS MUNICIPALES DE JUVENTUD ELECTOS CON COLOMBIA LIDER Y LA RAP CARIBE (Tipo Banco: Banco de Gestiones) (Meta de la gestión: 0) RUTA DE LA LECTURA JUVENIL. (Tipo Banco: Banco de Gestiones) (Meta de la gestión: ) CAPACITACIÓN EN CUIDADO DEL MEDIO AMBIENTE CON JOVENES DEL MUNICIPIO DE COLOSO (Tipo Banco: Banco de Gestiones) (Meta de la gestión: 50) | AI12: CAMPAÑA SUCRE TERRITORIO JOVEN EN LA INSTITUCIÓN EDUCATIVA ALTOS DEL ROSARIO Y CAPACITACIÓN A LOS CONSEJEROS MUNICIPALES DE JUVENTUD ELECTOS CON COLOMBIA LIDER Y LA RAP CARIBE (Tipo de banco: Banco de Gestiones) (Meta de la gestión: 0) (Ejecutado: 195) RUTA DE LA LECTURA JUVENIL. (Tipo de banco: Banco de Gestiones) (Meta de la gestión: ) (Ejecutado: 53) CAPACITACIÓN EN CUIDADO DEL MEDIO AMBIENTE CON JOVENES DEL MUNICIPIO DE COLOSO (Tipo de banco: Banco de Gestiones) (Meta de la gestión: 50) (Ejecutado: 32) | AJ12: Sensibilizacion dia de las manos rojas para entornos protectores. Prevencion del consumo de sustancias psicoactivas y embarazo adolescentes. Sensibilizacion en genro, diversidad sexual y no violencia. Jornada de formacion ambiental juvenil. Sensibilizacion en salud mental y buen uso dela inteligencia artificial. Capacitacion en uso responsable y creativo de las TICS. Formacion ambiental juvenil. Charla pedagogica sobre salud mental. (Meta Programada: 693) (Tipo de Banco: Banco de Gestiones) | AK12: Sensibilizacion dia de las manos rojas para entornos protectores. Prevencion del consumo de sustancias psicoactivas y embarazo adolescentes. Sensibilizacion en genro, diversidad sexual y no violencia. Jornada de formacion ambiental juvenil. Sensibilizacion en salud mental y buen uso dela inteligencia artificial. Capacitacion en uso responsable y creativo de las TICS. Formacion ambiental juvenil. Charla pedagogica sobre salud mental. (Meta programada: 693) (Ejecución: 693) (Tipo de banco: Banco de Gestiones) | AP12: 280 | AQ12: 1 | AR12: Superior | AS12: 693 | AT12: 1 | AU12: Superior | AV12: 973 | AW12: 1 | AX12: Superior | AY12: 0 | AZ12: 0 | BA12: 0 | BB12: 0 | BC12: 0 | BD12: 0 | BE12: 0 | BF12: 0 | BG12: 0 | BH12: 0 | BI12: 0 | BJ12: 0 | BK12: 0 | BL12: 0 | BM12: 0 | BN12: 0 | BO12: 0 | BP12: 0 | BQ12: 0 | BR12: 0 | BS12: 0 | BT12: 0 | BU12: 0 | BV12: 0 | BW12: 0 | BX12: 0 | BY12: 0 | BZ12: 0 | CA12: 0 | CB12: 0 | CC12: 0 | CD12: 0 | CE12: 0 | CF12: 0 | CG12: 0 | CH12: 0 | CI12: 0 | CJ12: 0 | CK12: 0 | CL12: 0 | CM12: 0 | CN12: 0 | CO12: 0 | CP12: 0 | CQ12: 0 | CR12: Se tenia previsto formular proyecto, pero no cuenta con financiación | CS12: Mujeres, jovenes, niños, niñas y adolescentes y familias capacitados con formaciones para su crecimiento academico y autonomia economica
A13: MT010 | B13: 1 | C13: Transformación del Ser Humano | D13: Porcentaje de ejecución de las actividades del Plan de acción de la Política Pública para el fortalecimiento integral de las familias de sucre 2023-2037 | E13: 0 | F13: Porcentaje | G13: 2023 | H13: Informe de avance Política Pública para el fortalecimiento integral de las familias | I13: 0,25 | J13: 3. Salud y bienestar 10- Reducción de las desigualdades. | K13: Inclusión Social | L13: 3 | M13: Familias con Oportunidades | N13: Inclusión Social y Reconciliación | O13: 41 | P13: Desarrollo integral de la primera infancia a la juventud, y fortalecimiento de las capacidades de las familias de niñas, niños y adolescentes | Q13: 4102 | R13: Servicios de educación informal a niños, niñas, adolescentes y jóvenes para el reconocimiento de sus derechos | S13: 4102045 | T13: Personas capacitadas | U13: 410204500 | V13: Servicios mediante los cuales se socializan a los niños, niñas, adolescentes y jóvenes; al igual que a sus padres, madres, cuidadores y docentes, los temas relacionados con el reconocimiento de los derechos de la niñez, la adolescencia y la juventud. | W13: Número de personas | X13: No | Y13: Número | Z13: 150 | AA13: Acumulativo | AB13: Secretaria de Inclusión Social, Mujer y Equidad de Genero | AC13: 0 | AD13: 50 | AE13: 50 | AF13: 50 | AG13: SE ASISTIERON TECNICAMENTE 174 PERSONAS EN LOS TEMAS DE: MARCO LEGAL Y CONSTITUCIONAL DE FAMILIAS, POLITICA PUBLICA DE FAMILIAS, ENTRE OTROS (BPIN: Por Gestión) (Meta del Proyecto: 174) (Ejecución 2024: 174) | AH13: CAPACITAR A FAMILIAS POR AÑO EN EL RESCATE DE LOS VALORES Y EL FORTALECIMIENTO FAMILIAR EN EL MARCO DEL MES DE LA FAMILIA (Tipo Banco: Banco de Gestiones) (Meta de la gestión: 50) | AI13: CAPACITAR A FAMILIAS POR AÑO EN EL RESCATE DE LOS VALORES Y EL FORTALECIMIENTO FAMILIAR EN EL MARCO DEL MES DE LA FAMILIA (Tipo de banco: Banco de Gestiones) (Meta de la gestión: 50) (Ejecutado: 50) | AJ13: CAPACITAR A 50 FAMILIAS POR AÑO EN EL RESCATE DE LOS VALORES Y EL FORTALECIMIENTO FAMILIAR EN EL MARCO DEL MES DE LA FAMILIA Implementación DE ACCIONES DE APOYO PSICOSOCIAL COMO ESTRATEGIA FRENTE A LAS PROBLEMÁTICAS DE SALUD MENTAL EN EL DEPARTAMENTO DE Sucre (BPIN: 202500000050658) (Meta del proyecto: 1040) (Tipo de Banco: Banco Territorial) | AL13: CAPACITAR A 50 FAMILIAS POR AÑO EN EL RESCATE DE LOS VALORES Y EL FORTALECIMIENTO FAMILIAR EN EL MARCO DEL MES DE LA FAMILIA | AM13: 174 | AN13: 1 | AO13: Superior | AP13: 50 | AQ13: 1 | AR13: Superior | AT13: 1 | AU13: Superior | AV13: 224 | AW13: 1 | AX13: Superior | AY13: 0 | AZ13: 0 | BA13: 0 | BB13: 0 | BC13: 0 | BD13: 0 | BE13: 0 | BF13: 0 | BG13: 0 | BH13: 0 | BI13: 0 | BJ13: 0 | BK13: 0 | BL13: 0 | BM13: 0 | BN13: 0 | BO13: 0 | BP13: 0 | BQ13: 0 | BR13: 0 | BS13: 0 | BT13: 0 | BU13: 0 | BV13: 0 | BW13: 0 | BX13: 0 | BY13: 0 | BZ13: 0 | CA13: 0 | CB13: 0 | CC13: 0 | CD13: 0 | CE13: 0 | CF13: 0 | CG13: 0 | CH13: 0 | CI13: 0 | CJ13: 0 | CK13: 0 | CL13: 0 | CM13: 0 | CN13: 0 | CO13: 0 | CP13: 0 | CQ13: 0 | CS13: Mujeres, jovenes, niños, niñas y adolescentes y familias capacitados con formaciones para su crecimiento academico y autonomia economica
A14: MT011 | B14: 3 | C14: Transformación del Ser Humano | D14: Porcentaje de ejecución de las actividades del Plan de acción de la Política Pública para el fortalecimiento integral de las familias de sucre 2023-2037 | E14: 0 | F14: Porcentaje | G14: 2023 | H14: Informe de avance Política Pública para el fortalecimiento integral de las familias | I14: 0,25 | J14: 3. Salud y bienestar 10- Reducción de las desigualdades. | K14: Inclusión Social | L14: 3 | M14: Familias con Oportunidades | N14: Inclusión Social y Reconciliación | O14: 41 | P14: Desarrollo integral de la primera infancia a la juventud, y fortalecimiento de las capacidades de las familias de niñas, niños y adolescentes | Q14: 4102 | R14: Servicio de promoción de temas de dinámica relacional y desarrollo autónomo | S14: 4102043 | T14: Familias atendidas | U14: 410204300 | V14: Incluye el desarrollo de acciones de asesoría, orientación y acompañamiento a las familias, que buscan generar cultura en las familias y las comunidades sobre vínculos de cuidado mutuo en las situaciones de dinámica relacional o en aquellas que requieran apoyo ante situaciones de vulnerabilidad sociocultural o de garantía de derechos. | W14: Número de familias | X14: No | Y14: Número | Z14: 820 | AA14: No acumulativo | AB14: Secretaria de Inclusión Social, Mujer y Equidad de Genero | AC14: 820 | AD14: 820 | AE14: 820 | AF14: 820 | AG14: SUCRE ESCUCHA EN EL DEPARTAMENTO DE SUCRE (BPIN: 2022000020011) (Meta del Proyecto: 2600) (Ejecución 2024: 2600) APOYO PARA LA REALIZACIÓN DE ACTIVIDADES RECREATIVAS, CULTURALES Y DE EMPRENDIMIENTO EN EL MARCO DEL MES DE LA FAMILIA 2024 EL DEPARTAMENTO DE SUCRE (BPIN: 2024002700060) (Meta del Proyecto: ) (Ejecución 2024: 1) | AH14: Apuesta institucional de la estrategia SUCRE TERRITORIO DE FAMILIAS UNIDAS (Tipo Banco: Banco de Gestiones) (Meta de la gestión: 388) APOYO PARA LA REALIZACIÓN DE ACTIVIDADES RECREATIVAS, CULTURALES Y DE EMPRENDIMIENTO EN EL MARCO DEL MES DE LA FAMILIA 2025 EL DEPARTAMENTO DE SUCRE (BPIN: 202400000004252) (Tipo de Banco: Banco Territorial) | AI14: Apoyo PARA LA REALIZACIÓN DE ACTIVIDADES RECREATIVAS, CULTURALES, Y DE EMPRENDIMIENTO EN EL MARCO DEL MES DE LA FAMILIA 2025 EN EL DEPARTAMENTO DE Sucre (Bpin: 202400000004252) (Tipo de Banco: Banco Territorial) (Meta total del indicador: 432.0) (Meta total de la vigencia: 432.0) (Ejecutado: 432.0) Apuesta institucional de la estrategia SUCRE TERRITORIO DE FAMILIAS UNIDAS (Tipo de banco: Banco de Gestiones) (Meta de la gestión: 388) (Ejecutado: 388) | AJ14: INICIATIVA DE IMPLEMENTACIÓN DE ACTIVIDADES DE LA POLÍTICA PÚBLICA DE FAMILIA SUCRE ESCUCHA FAMILIA Fortalecimiento DE CAPACIDADES PSICOSOCIALES, PRODUCTIVAS Y PARTICIPATIVAS DE LAS FAMILAS VULNERABLES DEL DEPARTAMENTO DE Sucre (BPIN: 202600000005053) (Meta del proyecto: 297) (Tipo de Banco: Banco Territorial) Jornada de sensibilización a los padres de familia de la Institución Educativa La Unión (Meta Programada: 820) (Tipo de Banco: Banco de Gestiones) | AK14: Jornada de sensibilización a los padres de familia de la Institución Educativa La Unión (Meta programada: 820) (Ejecución: 620) (Tipo de banco: Banco de Gestiones) | AL14: INICIATIVA DE IMPLEMENTACIÓN DE ACTIVIDADES DE LA POLÍTICA PÚBLICA DE FAMILIA (Bpin: ) | AM14: 2601 | AN14: 1 | AO14: Superior | AP14: 820 | AQ14: 1 | AR14: Superior | AS14: 620 | AT14: 1 | AU14: Superior | AV14: 4041 | AW14: 1 | AX14: Superior | AY14: 50000000 | AZ14: 0 | BA14: 0 | BB14: 0 | BC14: 0 | BD14: 0 | BE14: 0 | BF14: 0 | BG14: 1000000000 | BH14: 0 | BI14: 1050000000 | BJ14: 52500000 | BK14: 0 | BL14: 0 | BM14: 0 | BN14: 0 | BO14: 0 | BP14: 0 | BQ14: 0 | BR14: 1000000000 | BS14: 0 | BT14: 1052500000 | BU14: 55125000 | BV14: 0 | BW14: 0 | BX14: 0 | BY14: 0 | BZ14: 0 | CA14: 0 | CB14: 0 | CC14: 1000000000 | CD14: 0 | CE14: 1055125000 | CF14: 57881250 | CG14: 0 | CH14: 0 | CI14: 0 | CJ14: 0 | CK14: 0 | CL14: 0 | CM14: 0 | CN14: 1000000000 | CO14: 0 | CP14: 1057881250 | CQ14: 4215506250 | CR14: - El proyecto de mes de la familia para 2024 fue homologado porque se formuló con un indicador de Sucre Diferente - Se dio orientación de mantenimiento porque se está programando sobrecumplir la meta con los proyectos que asociaron | CS14: Sucre escucha familia
A15: MT012 | B15: 4 | C15: Transformación del Ser Humano | D15: Porcentaje de ejecución de las actividades del Plan de acción de la Política Pública para el fortalecimiento integral de las familias de sucre 2023-2037 | E15: 0 | F15: Porcentaje | G15: 2023 | H15: Informe de avance Política Pública para el fortalecimiento integral de las familias | I15: 0,25 | J15: 3. Salud y bienestar 10- Reducción de las desigualdades. | K15: Inclusión Social | L15: 3 | M15: Familias con Oportunidades | N15: Gobierno Territorial | O15: 45 | P15: Fortalecimiento del buen gobierno para el respeto y garantía de los derechos humanos | Q15: 4502 | R15: Servicio de apoyo financiero para la implementación de proyectos en materia de derechos humanos | S15: 4502021 | T15: Proyectos cofinanciados | U15: 450202100 | V15: Contempla la asignación de recursos financieros a iniciativas en temas relacionados con derechos humanos y el Derecho Internacional Humanitario. | W15: Número de proyectos | X15: No | Y15: Número | Z15: 1 | AA15: Acumulativo | AB15: Secretaria de Inclusión Social, Mujer y Equidad de Genero | AC15: 0 | AD15: 0 | AE15: 1 | AF15: 0 | AH15: IMPLEMENTACION DE UNA ESTRATEGIA DE APROPIACION CULTURAL PARA LAS FAMILIAS INDIGENAS DEL DEPARTAMENTO DE SUCRE (Tipo Banco: Banco de Gestiones) (Meta de la gestión: ) Fortalecimiento Productivo y Comercial para Familias Artesanas Indígenas Víctimas de Violencia Intrafamiliar en el Departamento de Sucre (Por Formular) (BPIN: ) (Tipo de Banco: Sin Tipo de Banco) | AJ15: BANCO DE ALIMENTOS (BPIN: Por Gestión) | AP15: 0 | AT15: 0 | AU15: Minimo | AV15: 0 | AW15: 0 | AX15: Minimo | AY15: 75000000 | AZ15: 0 | BA15: 0 | BB15: 0 | BC15: 0 | BD15: 0 | BE15: 0 | BF15: 0 | BG15: 0 | BH15: 0 | BI15: 75000000 | BJ15: 78750000 | BK15: 0 | BL15: 0 | BM15: 0 | BN15: 0 | BO15: 0 | BP15: 0 | BQ15: 0 | BR15: 0 | BS15: 0 | BT15: 78750000 | BU15: 82687500 | BV15: 0 | BW15: 0 | BX15: 0 | BY15: 0 | BZ15: 0 | CA15: 0 | CB15: 0 | CC15: 0 | CD15: 0 | CE15: 82687500 | CF15: 86821875 | CG15: 0 | CH15: 0 | CI15: 0 | CJ15: 0 | CK15: 0 | CL15: 0 | CM15: 0 | CN15: 0 | CO15: 0 | CP15: 86821875 | CQ15: 323259375 | CR15: Se realizo el cambio de vigencia de la iniciativa BANCO DE ALIMENTOS (Por gestión de cofinanciación) | CS15: Banco de alimentos
A16: MT013 | B16: 1 | C16: Transformación del Ser Humano | D16: Porcentaje de ejecución de las actividades del Plan de Acción de la Política Pública Departamental para la protección del adulto mayor | E16: 0,5 | F16: Porcentaje | G16: 2023 | H16: Informe Politica Publica de Adulto Mayor | I16: 0,75 | J16: 3 Salud y bienestar | K16: Inclusión Social | L16: 4 | M16: Edad plateada con oportunidades | N16: Inclusión Social y Reconciliación | O16: 41 | P16: Atención integral de población en situación permanente de desprotección social y/o familiar | Q16: 4104 | R16: Servicio de atención y protección integral al adulto mayor | S16: 4104008 | T16: Adultos mayores atendidos con servicios integrales | U16: 410400800 | V16: Servicios integrales que incluyen aspectos relacionados con protección a la salud y bienestar social, educación, cultura, recreación, entorno físico y social favorable, productividad para los adultos mayores. | W16: Número de adultos mayores | X16: No | Y16: Número | Z16: 7200 | AA16: Acumulativo | AB16: Secretaria de Inclusión Social, Mujer y Equidad de Genero | AC16: 2800 | AD16: 1700 | AE16: 1700 | AF16: 1000 | AG16: FASES MUNICIPALES PROGRAMA NUEVO COMIENZO (BPIN: Por Gestión) (Meta del Proyecto: 932) (Ejecución 2024: 932) FORTALECIMIENTO DEL PROGRAMA DE ATENCIÓN INTEGRAL PARA LA PROTECCIÓN Y LOS DERECHOS DE LAS PERSONAS MAYORES DURANTE EL AÑO 2024 EN LOS CENTROS DE VIDA DEL DEPARTAMENTO DE SUCRE (BPIN: 2024002700107) (Meta del Proyecto: 2771) (Ejecución 2024: 2771) FASE DEPARTAMENTAL PROGRAMA NUEVO COMIENZO (BPIN: Por Gestión) (Meta del Proyecto: 65) (Ejecución 2024: 65) | AH16: APOYO A LOS CENTROS DE BIENESTAR PARA LA ATENCIÓN INTEGRAL DE LAS PERSONAS MAYORES DURANTE EL AÑO 2024 EN LOS MUNICIPIOS DE SAN MARCOS Y SAN ONOFRE DEL DEPARTAMENTO DE SUCRE (BPIN: 2024002700106) (Tipo de Banco: Banco Territorial) FORTALECIMIENTO DEL PROGRAMA DE ATENCIÓN INTEGRAL PARA LA PROTECCIÓN Y GARANTÍA DE LOS DERECHOS DE LAS PERSONAS MAYORES DURANTE EL AÑO 2025 EN LOS CENTROS DE VIDA DEL DEPARTAMENTO DE SUCRE (BPIN: 202500000026392) (Tipo de Banco: Banco Territorial) APOYO A LOS CENTROS DE BIENESTAR PARA LA ATENCIÓN INTEGRAL DE LAS PERSONAS MAYORES DURANTE EL AÑO 2025 EN LOS MUNICIPIOS DE SAN MARCOS, SAN ONOFRE Y SINCELEJO EN EL DEPARTAMENTO DE SUCRE (BPIN: ) (Tipo de Banco: Banco Territorial) FORTALECIMIENTO E IMPLEMENTACION DE ACTIVIDADES DE LA POLITICA PUBLICA DEL ADULTO MAYOR EN EL MARCO DEL MES POBLACIONAL EN EL DEPARTAMENTO DE SUCRE (BPIN: ) (Tipo de Banco: Banco Territorial) FOMENTO Y FORTALECIMIENTO DE UNIDADES PRODUCTIVAS PARA LA PERSONA MAYOR (BPIN: ) (Tipo de Banco: Banco Territorial) FORTALECIMIENTO DE LOS ESPACIOS DE PARTICIPACIÓN DE LA PERSONA MAYOR EN EL MARCO DE LA ESTRATEGIA NACIONAL “NUEVO COMIENZO OTRO MOTIVO PARA VIVIR 2024 DEL DEPARTAMENTO DE SUCRE (BPIN: 2024002700097) (Tipo de Banco: Banco Territorial) Fortalecimiento DE LOS ESPACIOS DE PARTICIPACIÓN DE LA PERSONA MAYOR EN EL MARCO DE LA ESTRATEGIA NACIONAL “NUEVO COMIENZO OTRO MOTIVO PARA VIVIR" 2025 DEL DEPARTAMENTO DE Sucre (BPIN: 202500000032732) (Tipo de Banco: Banco Territorial) | AI16: Fortalecimiento DE LOS ESPACIOS DE PARTICIPACIÓN DE LA PERSONA MAYOR EN EL MARCO DE LA ESTRATEGIA NACIONAL “NUEVO COMIENZO OTRO MOTIVO PARA VIVIR" 2025 DEL DEPARTAMENTO DE Sucre (Bpin: 202500000032732) (Tipo de Banco: Banco Territorial) (Meta total del indicador: 10.0) (Meta total de la vigencia: 10.0) (Ejecutado: 10.0) Fortalecimiento DE LOS ESPACIOS DE PARTICIPACIÓN DE LA PERSONA MAYOR EN EL MARCO DE LA ESTRATEGIA NACIONAL NUEVO COMIENZO OTRO MOTIVO PARA VIVIR 2024 DEL DEPARTAMENTO DE Sucre (Bpin: 2024002700097) (Tipo de Banco: Banco Territorial) (Meta total del indicador: 12.0) (Meta total de la vigencia: 12.0) (Ejecutado: 12.0) Apoyo A LOS CENTROS DE BIENESTAR PARA LA ATENCIÓN INTEGRAL DE LAS PERSONAS MAYORES DURANTE EL AÑO 2024 EN LOS MUNICIPIOS DE SAN MARCOS Y SAN ONOFRE DEL DEPARTAMENTO DE Sucre (Bpin: 2024002700106) (Tipo de Banco: Banco Territorial) (Meta total del indicador: 55.0) (Meta total de la vigencia: 55.0) (Ejecutado: 22.0) Fortalecimiento del Programa de atención integral para la protección y garantía de los derechos de las personas mayores durante el año 2025en los Centros de Vida del Departamento de Sucre (Bpin: 202500000026392) (Tipo de Banco: Banco Territorial) (Meta total del indicador: 2473.0) (Meta total de la vigencia: 2473.0) (Ejecutado: 2473.0) | AJ16: Apoyo AL CENTRO DE BIENESTAR PARA LA ATENCIÓN INTEGRAL DE LAS PERSONAS MAYORES DURANTE EL AÑO 2025 EN EL MUNICIPIO DE SAN ONOFRE, EN EL DEPARTAMENTO DE Sucre (BPIN: 202500000034941) (Meta del proyecto: 22) (Tipo de Banco: Banco Territorial) (Estado en Portafolio: En Ejecución) FORTALECIMIENTO DEL PROGRAMA DE ATENCIÓN INTEGRAL PARA LA PROTECCIÓN Y LOS DERECHOS DE LAS PERSONAS MAYORES DURANTE EL AÑO 2026 EN LOS CENTROS DE VIDA DEL DEPARTAMENTO DE SUCRE APOYO A LOS CENTROS DE BIENESTAR PARA LA ATENCIÓN INTEGRAL DE LAS PERSONAS MAYORES DURANTE EL AÑO 2026 EN LOS MUNICIPIOS DE SAN MARCOS, SAN ONOFRE Y SINCELEJO EN EL DEPARTAMENTO DE SUCRE FORTALECIMIENTO DE LOS ESPACIOS DE PARTICIPACIÓN DE LA PERSONA MAYOR EN EL MARCO DE LA ESTRATEGIA NACIONAL “NUEVO COMIENZO OTRO MOTIVO PARA VIVIR DEL DEPARTAMENTO DE SUCRE FASES MUNICIPALES PROGRAMA NUEVO COMIENZO (BPIN: Por Gestión) FORTALECIMIENTO DE EMPRENDIMIENTOS DE LAS PERSONAS MAYORES EN ETAPA PRODUCTIVA EN EL DEPARTAMENTO DE SUCRE | AL16: FASES MUNICIPALES PROGRAMA NUEVO COMIENZO (Bpin: Por Gestión) FORTALECIMIENTO DE LOS ESPACIOS DE PARTICIPACIÓN DE LA PERSONA MAYOR EN EL MARCO DE LA ESTRATEGIA NACIONAL “NUEVO COMIENZO OTRO MOTIVO PARA VIVIR DEL DEPARTAMENTO DE SUCRE APOYO A LOS CENTROS DE BIENESTAR PARA LA ATENCIÓN INTEGRAL DE LAS PERSONAS MAYORES DURANTE EL AÑO 2027 EN LOS MUNICIPIOS DE SAN MARCOS, SAN ONOFRE Y SINCELEJO EN EL DEPARTAMENTO DE SUCRE FORTALECIMIENTO DEL PROGRAMA DE ATENCIÓN INTEGRAL PARA LA PROTECCIÓN Y LOS DERECHOS DE LAS PERSONAS MAYORES DURANTE EL AÑO 2027 EN LOS CENTROS DE VIDA DEL DEPARTAMENTO DE SUCRE | AM16: 3768 | AN16: 1 | AO16: Superior | AP16: 2517 | AQ16: 1 | AR16: Superior | AT16: 1 | AU16: Superior | AV16: 6285 | AW16: 0.87291667 | AX16: Alto | AY16: 0 | AZ16: 5.8067529e+09 | BA16: 0 | BB16: 0 | BC16: 0 | BD16: 0 | BE16: 0 | BF16: 0 | BG16: 0 | BH16: 0 | BI16: 5.8067529e+09 | BJ16: 0 | BK16: 7.766532e+09 | BL16: 0 | BM16: 0 | BN16: 0 | BO16: 0 | BP16: 0 | BQ16: 0 | BR16: 0 | BS16: 0 | BT16: 7.766532e+09 | BU16: 0 | BV16: 8.2325239e+09 | BW16: 0 | BX16: 0 | BY16: 0 | BZ16: 0 | CA16: 0 | CB16: 0 | CC16: 0 | CD16: 0 | CE16: 8.2325239e+09 | CF16: 0 | CG16: 8.7264754e+09 | CH16: 0 | CI16: 0 | CJ16: 0 | CK16: 0 | CL16: 0 | CM16: 0 | CN16: 0 | CO16: 0 | CP16: 8.7264754e+09 | CQ16: 3.0532284e+10 | CR16: - Los beneficiarios de cada año para adulto mayor, están sobre pasando la meta. - Hay dos proyectos para apoyo al emprendimiento de la persona mayor, uno para 2025 que se propondría por recursos propios (mínimo una mínima) y uno para 2026 que es un proyecto grande ($2.500millones) 03/10/2024: Se tiene una meta de cuatrienio por 7.200, pero en la meta por vigencia suman aproximadamente 15.500, se definio con el profesional que esta meta debe ser de mantenimiento, Pasandode 7.200 a 3.000. El numero de benefiriarios se presentan de la siguiente manetar, 2771 centro vida y centro de bienestar 55. | CS16: Centro de bienestar del adulto mayor, programa edad plateada con oportunidades
A17: MT014 | B17: 2 | C17: Transformación del Ser Humano | D17: Porcentaje de ejecución de las actividades del Plan de Acción de la Política Pública Departamental para la protección del adulto mayor | E17: 0,5 | F17: Porcentaje | G17: 2023 | H17: Informe Politica Publica de Adulto Mayor | I17: 0,75 | J17: 3 Salud y bienestar | K17: Inclusión Social | L17: 4 | M17: Edad plateada con oportunidades | N17: Inclusión Social y Reconciliación | O17: 41 | P17: Atención integral de población en situación permanente de desprotección social y/o familiar | Q17: 4104 | R17: Servicio de educación informal a los cuidadores del adulto mayor | S17: 4104010 | T17: Cuidadores cualificados | U17: 410401000 | V17: Servicios dirigidos a fortalecer las habilidades y competencias de los cuidadores del adulto mayor en temas de protección y atención integral a esta población. | W17: Número de cuidadores | X17: No | Y17: Número | Z17: 80 | AA17: Acumulativo | AB17: Secretaria de Inclusión Social, Mujer y Equidad de Genero | AC17: 0 | AD17: 30 | AE17: 30 | AF17: 20 | AH17: Formación a cuidadores de personas mayores en los centros vida del Departamento de Sucre. (Tipo Banco: Banco de Gestiones) (Meta de la gestión: ) | AI17: Formación a cuidadores de personas mayores en los centros vida del Departamento de Sucre. (Tipo de banco: Banco de Gestiones) (Meta de la gestión: ) (Ejecutado: 271) | AJ17: IMPLEMENTACIÓN DEL SISTEMA INTEGRAL DE CUIDADO DIRIGIDO A LA PRIMERA INFANCIA, PERSONAS CON DISCAPACIDAD Y PERSONAS MAYORES FORMACIÓN EN EMPRENDIMIENTO A CUIDADORAS DE PERSONAS MAYORES | AL17: FORMACIÓN EN EMPRENDIMIENTO A CUIDADORAS DE PERSONAS MAYORES (Bpin: ) | AP17: 271 | AQ17: 1 | AR17: Superior | AT17: 1 | AU17: Superior | AV17: 271 | AW17: 1 | AX17: Superior | AY17: 0 | AZ17: 314620000 | BA17: 0 | BB17: 0 | BC17: 0 | BD17: 0 | BE17: 0 | BF17: 0 | BG17: 0 | BH17: 0 | BI17: 314620000 | BJ17: 0 | BK17: 354550000 | BL17: 0 | BM17: 0 | BN17: 0 | BO17: 0 | BP17: 0 | BQ17: 0 | BR17: 0 | BS17: 0 | BT17: 354550000 | BU17: 0 | BV17: 354820000 | BW17: 0 | BX17: 0 | BY17: 0 | BZ17: 0 | CA17: 0 | CB17: 0 | CC17: 0 | CD17: 0 | CE17: 354820000 | CF17: 0 | CG17: 423090000 | CH17: 0 | CI17: 0 | CJ17: 0 | CK17: 0 | CL17: 0 | CM17: 0 | CN17: 0 | CO17: 0 | CP17: 423090000 | CQ17: 1447080000 | CR17: Esta meta se encuentra incluida en el proyecto de cuidadores del programa soy capaz | CS17: Cuidadores de poblaciòn adulto mayor y personas en condiciòn de discapacidad capacitados
